Workbook

Sheet MUESTREO
B3: EMPRESA | C3: DEPARTAMENTO | D3: CARGO | E3: EVALUADO | F3: FECHA | G3: DEPARTAMENTO SOPORTE | H3: CARGO SOPORTE | I3: ACTIVIDAD | J3: PROCESO | K3: ACCIONES | L3: TIPO DE ANALISIS | M3: DEPARTAMENTO ENC | N3: TIEMPO INICIO | O3: TIEMPO FIN | P3: TIEMPO | Q3: OBSERVACIONES | R3: OPORTUNIDADES DE MEJORA
B4: TSER | C4: CONTABILIDAD | D4: ANALISTA CONTABLE 2 EXPORTADORAS | E4: GERALDINE NAULA | F4: 45971 | I4: CONSOLIDACIÓN DE VENTAS CÍAS RELACIONADAS A MLC | J4: =IFERROR(VLOOKUP(MUESTREO_LABORAL_A2[[#This Row],[ACTIVIDAD]],'Lista Maestra'!$D$6:$F$190,3,0),"") -> CONCILIACIÓN DE VENTAS Y COMPRAS ENTRE RELACIONADAS | K4: =IFERROR(VLOOKUP(MUESTREO_LABORAL_A2[[#This Row],[ACTIVIDAD]],'Lista Maestra'!$D$6:$F$190,2,0),"") -> REALIZACIÓN Y ANÁLISIS DE CONCILIACIONES DE VENTAS ENTRE EXPORTADORAS RELACIONADAS PARA VERIFICAR QUE LOS REGISTROS DE VENTAS ESTÉN CUADRADOS, IDENTIFICANDO DIFERENCIAS Y REGISTRANDO AJUSTES CONTABLES NECESARIOS. | L4: CON ACTIVIDAD | N4: 0.35416667 | O4: 0.36805556 | P4: =IF(MUESTREO_LABORAL_A2[[#This Row],[TIEMPO INICIO]]="","",(MUESTREO_LABORAL_A2[[#This Row],[TIEMPO FIN]]-MUESTREO_LABORAL_A2[[#This Row],[TIEMPO INICIO]])*24) -> 0.33333333 | Q4: Viernes 07/11/2025 envió la conciliación de las exportadoras, comparativo de compras y ventas de compañías relacionadas, vale contra TFE, multi, y TSER. Actualización de la actividad realizada el día viernes 07/11/2025.
B5: TSER | C5: CONTABILIDAD | D5: ANALISTA CONTABLE 2 EXPORTADORAS | E5: GERALDINE NAULA | F5: 45971 | I5: FACTURACIÓN CIF BANANO A CLIENTES EN MULTINATIONAL | J5: =IFERROR(VLOOKUP(MUESTREO_LABORAL_A2[[#This Row],[ACTIVIDAD]],'Lista Maestra'!$D$6:$F$190,3,0),"") -> FACTURACIÓN A CLIENTES | K5: =IFERROR(VLOOKUP(MUESTREO_LABORAL_A2[[#This Row],[ACTIVIDAD]],'Lista Maestra'!$D$6:$F$190,2,0),"") -> ELABORACIÓN SEMANAL DE FACTURAS DE BANANO PARA CLIENTES INTERNACIONALES EN MULTINATIONAL, TRABAJANDO CON LOS REPORTES DE TRÁMITES DE LA SEMANA, DETALLE DE CONSOLIDACIÓN EN FTL Y B/LS CON CIERRE SEMANAL CORRESPONDIENTE. | L5: CON ACTIVIDAD | N5: 0.36805556 | O5: 0.38958333 | P5: =IF(MUESTREO_LABORAL_A2[[#This Row],[TIEMPO INICIO]]="","",(MUESTREO_LABORAL_A2[[#This Row],[TIEMPO FIN]]-MUESTREO_LABORAL_A2[[#This Row],[TIEMPO INICIO]])*24) -> 0.51666667 | Q5: Facturación se refiere al ingreso de facturas en base a una compra de producto. Va a hablar con Jennifer algún cambio de precio o si han habido ciertas divisiones.
B6: TSER | C6: CONTABILIDAD | D6: ANALISTA CONTABLE 2 EXPORTADORAS | E6: GERALDINE NAULA | F6: 45971 | I6: NECESIDADES BIOLÓGICAS | J6: =IFERROR(VLOOKUP(MUESTREO_LABORAL_A2[[#This Row],[ACTIVIDAD]],'Lista Maestra'!$D$6:$F$190,3,0),"") -> NECESIDADES BIOLÓGICAS | K6: =IFERROR(VLOOKUP(MUESTREO_LABORAL_A2[[#This Row],[ACTIVIDAD]],'Lista Maestra'!$D$6:$F$190,2,0),"") -> PROCESO DE MICCIÓN Y AGREGADOS | L6: SA | N6: 0.38958333 | O6: 0.39513889 | P6: =IF(MUESTREO_LABORAL_A2[[#This Row],[TIEMPO INICIO]]="","",(MUESTREO_LABORAL_A2[[#This Row],[TIEMPO FIN]]-MUESTREO_LABORAL_A2[[#This Row],[TIEMPO INICIO]])*24) -> 0.13333333
B7: TSER | C7: CONTABILIDAD | D7: ANALISTA CONTABLE 2 EXPORTADORAS | E7: GERALDINE NAULA | F7: 45971 | I7: FACTURACIÓN CIF BANANO A CLIENTES EN MULTINATIONAL | J7: =IFERROR(VLOOKUP(MUESTREO_LABORAL_A2[[#This Row],[ACTIVIDAD]],'Lista Maestra'!$D$6:$F$190,3,0),"") -> FACTURACIÓN A CLIENTES | K7: =IFERROR(VLOOKUP(MUESTREO_LABORAL_A2[[#This Row],[ACTIVIDAD]],'Lista Maestra'!$D$6:$F$190,2,0),"") -> ELABORACIÓN SEMANAL DE FACTURAS DE BANANO PARA CLIENTES INTERNACIONALES EN MULTINATIONAL, TRABAJANDO CON LOS REPORTES DE TRÁMITES DE LA SEMANA, DETALLE DE CONSOLIDACIÓN EN FTL Y B/LS CON CIERRE SEMANAL CORRESPONDIENTE. | L7: CON ACTIVIDAD | N7: 0.39513889 | O7: 0.41041667 | P7: =IF(MUESTREO_LABORAL_A2[[#This Row],[TIEMPO INICIO]]="","",(MUESTREO_LABORAL_A2[[#This Row],[TIEMPO FIN]]-MUESTREO_LABORAL_A2[[#This Row],[TIEMPO INICIO]])*24) -> 0.36666667 | Q7: Tuvo toda la información lista hasta que Jennifer le responda, como no le ha respondido, va a continuar con otra actividad.
B8: TSER | C8: CONTABILIDAD | D8: ANALISTA CONTABLE 2 EXPORTADORAS | E8: GERALDINE NAULA | F8: 45971 | I8: LIQUIDACIÓN - GASTOS ARROZ | J8: =IFERROR(VLOOKUP(MUESTREO_LABORAL_A2[[#This Row],[ACTIVIDAD]],'Lista Maestra'!$D$6:$F$190,3,0),"") -> LIQUIDACIÓN DE GASTOS | K8: =IFERROR(VLOOKUP(MUESTREO_LABORAL_A2[[#This Row],[ACTIVIDAD]],'Lista Maestra'!$D$6:$F$190,2,0),"") -> 0 | L8: ENC | N8: 0.41041667 | O8: 0.52083333 | P8: =IF(MUESTREO_LABORAL_A2[[#This Row],[TIEMPO INICIO]]="","",(MUESTREO_LABORAL_A2[[#This Row],[TIEMPO FIN]]-MUESTREO_LABORAL_A2[[#This Row],[TIEMPO INICIO]])*24) -> 2.65 | Q8: 11:14 vino Jennifer a decirle algo relacionado al arroz a Geraldine. Lo que sucede es que Jennifer tiene que desaplicar unas facuras (cuyo total es de 268.50 USD) que no corresponde a la cosecha puesto que a la cosecha del PAN corresponde algo relacionado al de la ISLA. | R8: Se puede crear una solución integral para establecer una mejor comunicación entre José Terán (de servicios auxiliares) y Contabilidad puesto que actualmente la gestión se la realiza mediante un papel y está presto a errores y confusiones.
B9: TSER | C9: CONTABILIDAD | D9: ANALISTA CONTABLE 2 EXPORTADORAS | E9: GERALDINE NAULA | F9: 45971 | I9: ALIMENTACIÓN | J9: =IFERROR(VLOOKUP(MUESTREO_LABORAL_A2[[#This Row],[ACTIVIDAD]],'Lista Maestra'!$D$6:$F$190,3,0),"") -> ALIMENTACIÓN | K9: =IFERROR(VLOOKUP(MUESTREO_LABORAL_A2[[#This Row],[ACTIVIDAD]],'Lista Maestra'!$D$6:$F$190,2,0),"") -> ALIMENTARSE | L9: ALIMENTACIÓN | N9: 0.52083333 | O9: 0.5625 | P9: =IF(MUESTREO_LABORAL_A2[[#This Row],[TIEMPO INICIO]]="","",(MUESTREO_LABORAL_A2[[#This Row],[TIEMPO FIN]]-MUESTREO_LABORAL_A2[[#This Row],[TIEMPO INICIO]])*24) -> 1
B10: TSER | C10: CONTABILIDAD | D10: ANALISTA CONTABLE 2 EXPORTADORAS | E10: GERALDINE NAULA | F10: 45971 | I10: NECESIDADES BIOLÓGICAS | J10: =IFERROR(VLOOKUP(MUESTREO_LABORAL_A2[[#This Row],[ACTIVIDAD]],'Lista Maestra'!$D$6:$F$190,3,0),"") -> NECESIDADES BIOLÓGICAS | K10: =IFERROR(VLOOKUP(MUESTREO_LABORAL_A2[[#This Row],[ACTIVIDAD]],'Lista Maestra'!$D$6:$F$190,2,0),"") -> PROCESO DE MICCIÓN Y AGREGADOS | L10: SA | N10: 0.5625 | O10: 0.56458333 | P10: =IF(MUESTREO_LABORAL_A2[[#This Row],[TIEMPO INICIO]]="","",(MUESTREO_LABORAL_A2[[#This Row],[TIEMPO FIN]]-MUESTREO_LABORAL_A2[[#This Row],[TIEMPO INICIO]])*24) -> 0.05
B11: TSER | C11: CONTABILIDAD | D11: ANALISTA CONTABLE 2 EXPORTADORAS | E11: GERALDINE NAULA | F11: 45971 | I11: LIQUIDACIÓN - GASTOS ARROZ | J11: =IFERROR(VLOOKUP(MUESTREO_LABORAL_A2[[#This Row],[ACTIVIDAD]],'Lista Maestra'!$D$6:$F$190,3,0),"") -> LIQUIDACIÓN DE GASTOS | K11: =IFERROR(VLOOKUP(MUESTREO_LABORAL_A2[[#This Row],[ACTIVIDAD]],'Lista Maestra'!$D$6:$F$190,2,0),"") -> 0 | L11: CON ACTIVIDAD | N11: 0.56458333 | O11: 0.57291667 | P11: =IF(MUESTREO_LABORAL_A2[[#This Row],[TIEMPO INICIO]]="","",(MUESTREO_LABORAL_A2[[#This Row],[TIEMPO FIN]]-MUESTREO_LABORAL_A2[[#This Row],[TIEMPO INICIO]])*24) -> 0.2 | Q11: José Terán solicita anticipos a financiero a medida de la cosecha del arroz, y hay facturas que nos llegan al sri y éstas nos llegan al SRI.
B12: TSER | C12: CONTABILIDAD | D12: ANALISTA CONTABLE 2 EXPORTADORAS | E12: GERALDINE NAULA | F12: 45971 | I12: DEFINICIÓN | J12: =IFERROR(VLOOKUP(MUESTREO_LABORAL_A2[[#This Row],[ACTIVIDAD]],'Lista Maestra'!$D$6:$F$190,3,0),"") -> DEFINICIÓN | K12: =IFERROR(VLOOKUP(MUESTREO_LABORAL_A2[[#This Row],[ACTIVIDAD]],'Lista Maestra'!$D$6:$F$190,2,0),"") -> DEFINIR PROCESOS Y CRITERIOS INGENIERILES | L12: DEFINICIÓN | N12: 0.57291667 | O12: 0.58055556 | P12: =IF(MUESTREO_LABORAL_A2[[#This Row],[TIEMPO INICIO]]="","",(MUESTREO_LABORAL_A2[[#This Row],[TIEMPO FIN]]-MUESTREO_LABORAL_A2[[#This Row],[TIEMPO INICIO]])*24) -> 0.18333333 | Q12: Geraldine me explica el tema de la cosecha del arroz.
B13: TSER | C13: CONTABILIDAD | D13: ANALISTA CONTABLE 2 EXPORTADORAS | E13: GERALDINE NAULA | F13: 45971 | G13: CONTABILIDAD | H13: ASISTENTE CONTABLE | I13: SOPORTE INGRESO DE FACTURAS DE COMPRAS | J13: =IFERROR(VLOOKUP(MUESTREO_LABORAL_A2[[#This Row],[ACTIVIDAD]],'Lista Maestra'!$D$6:$F$190,3,0),"") -> SUPERVISIÓN EN CIERRE | K13: =IFERROR(VLOOKUP(MUESTREO_LABORAL_A2[[#This Row],[ACTIVIDAD]],'Lista Maestra'!$D$6:$F$190,2,0),"") -> 0 | L13: CON ACTIVIDAD | N13: 0.58055556 | O13: 0.62222222 | P13: =IF(MUESTREO_LABORAL_A2[[#This Row],[TIEMPO INICIO]]="","",(MUESTREO_LABORAL_A2[[#This Row],[TIEMPO FIN]]-MUESTREO_LABORAL_A2[[#This Row],[TIEMPO INICIO]])*24) -> 1 | Q13: Le da soporte a Marly porque está en su periodo de lactancia.
B14: TSER | C14: CONTABILIDAD | D14: ANALISTA CONTABLE 2 EXPORTADORAS | E14: GERALDINE NAULA | F14: 45971 | I14: NECESIDADES BIOLÓGICAS | J14: =IFERROR(VLOOKUP(MUESTREO_LABORAL_A2[[#This Row],[ACTIVIDAD]],'Lista Maestra'!$D$6:$F$190,3,0),"") -> NECESIDADES BIOLÓGICAS | K14: =IFERROR(VLOOKUP(MUESTREO_LABORAL_A2[[#This Row],[ACTIVIDAD]],'Lista Maestra'!$D$6:$F$190,2,0),"") -> PROCESO DE MICCIÓN Y AGREGADOS | L14: SA | N14: 0.62222222 | O14: 0.625 | P14: =IF(MUESTREO_LABORAL_A2[[#This Row],[TIEMPO INICIO]]="","",(MUESTREO_LABORAL_A2[[#This Row],[TIEMPO FIN]]-MUESTREO_LABORAL_A2[[#This Row],[TIEMPO INICIO]])*24) -> 0.066666667
B15: TSER | C15: CONTABILIDAD | D15: ANALISTA CONTABLE 2 EXPORTADORAS | E15: GERALDINE NAULA | F15: 45972 | I15: FACTURACIÓN CIF BANANO A CLIENTES EN MULTINATIONAL | J15: =IFERROR(VLOOKUP(MUESTREO_LABORAL_A2[[#This Row],[ACTIVIDAD]],'Lista Maestra'!$D$6:$F$190,3,0),"") -> FACTURACIÓN A CLIENTES | K15: =IFERROR(VLOOKUP(MUESTREO_LABORAL_A2[[#This Row],[ACTIVIDAD]],'Lista Maestra'!$D$6:$F$190,2,0),"") -> ELABORACIÓN SEMANAL DE FACTURAS DE BANANO PARA CLIENTES INTERNACIONALES EN MULTINATIONAL, TRABAJANDO CON LOS REPORTES DE TRÁMITES DE LA SEMANA, DETALLE DE CONSOLIDACIÓN EN FTL Y B/LS CON CIERRE SEMANAL CORRESPONDIENTE. | L15: CON ACTIVIDAD | N15: 0.35416667 | O15: 0.39444444 | P15: =IF(MUESTREO_LABORAL_A2[[#This Row],[TIEMPO INICIO]]="","",(MUESTREO_LABORAL_A2[[#This Row],[TIEMPO FIN]]-MUESTREO_LABORAL_A2[[#This Row],[TIEMPO INICIO]])*24) -> 0.96666667
B16: TSER | C16: CONTABILIDAD | D16: ANALISTA CONTABLE 2 EXPORTADORAS | E16: GERALDINE NAULA | F16: 45972 | I16: CONTROL DE CUENTAS POR PAGAR Y REVISIÓN DE GASTOS OPERATIVOS EN EXPORTADORAS | J16: =IFERROR(VLOOKUP(MUESTREO_LABORAL_A2[[#This Row],[ACTIVIDAD]],'Lista Maestra'!$D$6:$F$190,3,0),"") -> SUPERVISIÓN EN CIERRE | K16: =IFERROR(VLOOKUP(MUESTREO_LABORAL_A2[[#This Row],[ACTIVIDAD]],'Lista Maestra'!$D$6:$F$190,2,0),"") -> SE REVISA Y CONTROLA LA INFORMACIÓN DE LAS CUENTAS POR PAGAR DE LAS EXPORTADORAS, VERIFICANDO QUE LAS FACTURAS DE COMPRA Y GASTOS OPERATIVOS ESTÉN CORRECTAMENTE REGISTRADOS, APROBADOS Y RESPALDADOS. SE REALIZAN SEGUIMIENTOS A LOS PROVEEDORES Y SE CONFIRMA QUE LOS VALORES COINCIDAN CON LOS REGISTROS CONTABLES. | L16: CON ACTIVIDAD | N16: 0.39444444 | O16: 0.40138889 | P16: =IF(MUESTREO_LABORAL_A2[[#This Row],[TIEMPO INICIO]]="","",(MUESTREO_LABORAL_A2[[#This Row],[TIEMPO FIN]]-MUESTREO_LABORAL_A2[[#This Row],[TIEMPO INICIO]])*24) -> 0.16666667 | Q16: ahorita pare un rato lo de la facturacion porque ingresare un NC que me solicito angelo eso es cuentas por pagar
B17: TSER | C17: CONTABILIDAD | D17: ANALISTA CONTABLE 2 EXPORTADORAS | E17: GERALDINE NAULA | F17: 45972 | I17: FACTURACIÓN CIF BANANO A CLIENTES EN MULTINATIONAL | J17: =IFERROR(VLOOKUP(MUESTREO_LABORAL_A2[[#This Row],[ACTIVIDAD]],'Lista Maestra'!$D$6:$F$190,3,0),"") -> FACTURACIÓN A CLIENTES | K17: =IFERROR(VLOOKUP(MUESTREO_LABORAL_A2[[#This Row],[ACTIVIDAD]],'Lista Maestra'!$D$6:$F$190,2,0),"") -> ELABORACIÓN SEMANAL DE FACTURAS DE BANANO PARA CLIENTES INTERNACIONALES EN MULTINATIONAL, TRABAJANDO CON LOS REPORTES DE TRÁMITES DE LA SEMANA, DETALLE DE CONSOLIDACIÓN EN FTL Y B/LS CON CIERRE SEMANAL CORRESPONDIENTE. | L17: CON ACTIVIDAD | N17: 0.40138889 | O17: 0.51111111 | P17: =IF(MUESTREO_LABORAL_A2[[#This Row],[TIEMPO INICIO]]="","",(MUESTREO_LABORAL_A2[[#This Row],[TIEMPO FIN]]-MUESTREO_LABORAL_A2[[#This Row],[TIEMPO INICIO]])*24) -> 2.6333333
B18: TSER | C18: CONTABILIDAD | D18: ANALISTA CONTABLE 2 EXPORTADORAS | E18: GERALDINE NAULA | F18: 45972 | G18: CERTIFICACIONES | H18: ASISTENTE EN CERTIFICACIONES | I18: CAPACITACIÓN Y ASISTENCIA EN SAP A OTROS DEPARTAMENTOS | J18: =IFERROR(VLOOKUP(MUESTREO_LABORAL_A2[[#This Row],[ACTIVIDAD]],'Lista Maestra'!$D$6:$F$190,3,0),"") -> SOPORTE CONTABLE | K18: =IFERROR(VLOOKUP(MUESTREO_LABORAL_A2[[#This Row],[ACTIVIDAD]],'Lista Maestra'!$D$6:$F$190,2,0),"") -> SE BRINDA CAPACITACIÓN Y ASISTENCIA EN EL USO DE SAP A OTROS DEPARTAMENTOS, EXPLICANDO PROCESOS CONTABLES, FUNCIONALIDADES DEL SISTEMA Y PROCEDIMIENTOS PARA EL REGISTRO. | L18: CON ACTIVIDAD | N18: 0.51111111 | O18: 0.51805556 | P18: =IF(MUESTREO_LABORAL_A2[[#This Row],[TIEMPO INICIO]]="","",(MUESTREO_LABORAL_A2[[#This Row],[TIEMPO FIN]]-MUESTREO_LABORAL_A2[[#This Row],[TIEMPO INICIO]])*24) -> 0.16666667 | Q18: Holis Jonathan ahorita estoy dando soporte a otro dep es certificaciones en este caso me estan solicitando un ruc
B19: TSER | C19: CONTABILIDAD | D19: ANALISTA CONTABLE 2 EXPORTADORAS | E19: GERALDINE NAULA | F19: 45972 | I19: SOPORTE INGRESO DE FACTURAS DE COMPRAS | J19: =IFERROR(VLOOKUP(MUESTREO_LABORAL_A2[[#This Row],[ACTIVIDAD]],'Lista Maestra'!$D$6:$F$190,3,0),"") -> SUPERVISIÓN EN CIERRE | K19: =IFERROR(VLOOKUP(MUESTREO_LABORAL_A2[[#This Row],[ACTIVIDAD]],'Lista Maestra'!$D$6:$F$190,2,0),"") -> 0 | L19: CON ACTIVIDAD | N19: 0.51805556 | O19: 0.52083333 | P19: =IF(MUESTREO_LABORAL_A2[[#This Row],[TIEMPO INICIO]]="","",(MUESTREO_LABORAL_A2[[#This Row],[TIEMPO FIN]]-MUESTREO_LABORAL_A2[[#This Row],[TIEMPO INICIO]])*24) -> 0.066666667 | Q19: ya le di la info a Ruben ahorita me escribio angelo para que ingrese una fc de consorcio entonces eso hare es CxP igual pero aun falta AFC porque jenn aun no me confirma un dato apenas jenn me confirme sigo con eso
B20: TSER | C20: CONTABILIDAD | D20: ANALISTA CONTABLE 2 EXPORTADORAS | E20: GERALDINE NAULA | F20: 45972 | I20: DEFINICIÓN | J20: =IFERROR(VLOOKUP(MUESTREO_LABORAL_A2[[#This Row],[ACTIVIDAD]],'Lista Maestra'!$D$6:$F$190,3,0),"") -> DEFINICIÓN | K20: =IFERROR(VLOOKUP(MUESTREO_LABORAL_A2[[#This Row],[ACTIVIDAD]],'Lista Maestra'!$D$6:$F$190,2,0),"") -> DEFINIR PROCESOS Y CRITERIOS INGENIERILES | L20: DEFINICIÓN | N20: 0.5625 | O20: 0.58194444 | P20: =IF(MUESTREO_LABORAL_A2[[#This Row],[TIEMPO INICIO]]="","",(MUESTREO_LABORAL_A2[[#This Row],[TIEMPO FIN]]-MUESTREO_LABORAL_A2[[#This Row],[TIEMPO INICIO]])*24) -> 0.46666667 | Q20: Definimos ciertas actividades pendientes y aquellas en las que da soporte a otros departamentos o compañeros de trabajo.
B21: TSER | C21: CONTABILIDAD | D21: ANALISTA CONTABLE 2 EXPORTADORAS | E21: GERALDINE NAULA | F21: 45972 | I21: ASIENTOS POR DESCUENTOS A EMPLEADOS MEDIANTE ROL | J21: =IFERROR(VLOOKUP(MUESTREO_LABORAL_A2[[#This Row],[ACTIVIDAD]],'Lista Maestra'!$D$6:$F$190,3,0),"") -> DESCUENTOS DE NÓMINA | K21: =IFERROR(VLOOKUP(MUESTREO_LABORAL_A2[[#This Row],[ACTIVIDAD]],'Lista Maestra'!$D$6:$F$190,2,0),"") -> REGISTRO Y ANÁLISIS DE ASIENTOS DE DIARIO O DE RECLASIFICACIÓN EN CUENTAS POR COBRAR DE EMPLEADOS POR DESCUENTOS INDICADOS POR EL ÁREA DE RRHH, VERIFICANDO LA CONSISTENCIA DE MONTOS, CLASIFICACIÓN CONTABLE CORRECTA | L21: CON ACTIVIDAD | N21: 0.58194444 | O21: 0.625 | P21: =IF(MUESTREO_LABORAL_A2[[#This Row],[TIEMPO INICIO]]="","",(MUESTREO_LABORAL_A2[[#This Row],[TIEMPO FIN]]-MUESTREO_LABORAL_A2[[#This Row],[TIEMPO INICIO]])*24) -> 1.0333333 | Q21: ahorita voy a registrar unos descuentos de nómina
B22: TSER | C22: CONTABILIDAD | D22: ANALISTA CONTABLE 2 EXPORTADORAS | E22: GERALDINE NAULA | F22: 45973 | I22: FACTURACIÓN CIF BANANO A CLIENTES EN MULTINATIONAL | J22: =IFERROR(VLOOKUP(MUESTREO_LABORAL_A2[[#This Row],[ACTIVIDAD]],'Lista Maestra'!$D$6:$F$190,3,0),"") -> FACTURACIÓN A CLIENTES | K22: =IFERROR(VLOOKUP(MUESTREO_LABORAL_A2[[#This Row],[ACTIVIDAD]],'Lista Maestra'!$D$6:$F$190,2,0),"") -> ELABORACIÓN SEMANAL DE FACTURAS DE BANANO PARA CLIENTES INTERNACIONALES EN MULTINATIONAL, TRABAJANDO CON LOS REPORTES DE TRÁMITES DE LA SEMANA, DETALLE DE CONSOLIDACIÓN EN FTL Y B/LS CON CIERRE SEMANAL CORRESPONDIENTE. | L22: CON ACTIVIDAD | N22: 0.35416667 | O22: 0.39722222 | P22: =IF(MUESTREO_LABORAL_A2[[#This Row],[TIEMPO INICIO]]="","",(MUESTREO_LABORAL_A2[[#This Row],[TIEMPO FIN]]-MUESTREO_LABORAL_A2[[#This Row],[TIEMPO INICIO]])*24) -> 1.0333333
B23: TSER | C23: CONTABILIDAD | D23: ANALISTA CONTABLE 2 EXPORTADORAS | E23: GERALDINE NAULA | F23: 45973 | I23: NECESIDADES BIOLÓGICAS | J23: =IFERROR(VLOOKUP(MUESTREO_LABORAL_A2[[#This Row],[ACTIVIDAD]],'Lista Maestra'!$D$6:$F$190,3,0),"") -> NECESIDADES BIOLÓGICAS | K23: =IFERROR(VLOOKUP(MUESTREO_LABORAL_A2[[#This Row],[ACTIVIDAD]],'Lista Maestra'!$D$6:$F$190,2,0),"") -> PROCESO DE MICCIÓN Y AGREGADOS | N23: 0.39722222 | O23: 0.40069444 | P23: =IF(MUESTREO_LABORAL_A2[[#This Row],[TIEMPO INICIO]]="","",(MUESTREO_LABORAL_A2[[#This Row],[TIEMPO FIN]]-MUESTREO_LABORAL_A2[[#This Row],[TIEMPO INICIO]])*24) -> 0.083333333
B24: TSER | C24: CONTABILIDAD | D24: ANALISTA CONTABLE 2 EXPORTADORAS | E24: GERALDINE NAULA | F24: 45973 | I24: FACTURACIÓN CIF BANANO A CLIENTES EN MULTINATIONAL | J24: =IFERROR(VLOOKUP(MUESTREO_LABORAL_A2[[#This Row],[ACTIVIDAD]],'Lista Maestra'!$D$6:$F$190,3,0),"") -> FACTURACIÓN A CLIENTES | K24: =IFERROR(VLOOKUP(MUESTREO_LABORAL_A2[[#This Row],[ACTIVIDAD]],'Lista Maestra'!$D$6:$F$190,2,0),"") -> ELABORACIÓN SEMANAL DE FACTURAS DE BANANO PARA CLIENTES INTERNACIONALES EN MULTINATIONAL, TRABAJANDO CON LOS REPORTES DE TRÁMITES DE LA SEMANA, DETALLE DE CONSOLIDACIÓN EN FTL Y B/LS CON CIERRE SEMANAL CORRESPONDIENTE. | L24: CON ACTIVIDAD | N24: 0.40069444 | O24: 0.44027778 | P24: =IF(MUESTREO_LABORAL_A2[[#This Row],[TIEMPO INICIO]]="","",(MUESTREO_LABORAL_A2[[#This Row],[TIEMPO FIN]]-MUESTREO_LABORAL_A2[[#This Row],[TIEMPO INICIO]])*24) -> 0.95
B25: TSER | C25: CONTABILIDAD | D25: ANALISTA CONTABLE 2 EXPORTADORAS | E25: GERALDINE NAULA | F25: 45973 | I25: RECLASIFICACIONES CONTABLES Y AJUSTES MENSUALES | J25: =IFERROR(VLOOKUP(MUESTREO_LABORAL_A2[[#This Row],[ACTIVIDAD]],'Lista Maestra'!$D$6:$F$190,3,0),"") -> ANÁLISIS DE CUENTAS | K25: =IFERROR(VLOOKUP(MUESTREO_LABORAL_A2[[#This Row],[ACTIVIDAD]],'Lista Maestra'!$D$6:$F$190,2,0),"") -> SE REALIZAN RECLASIFICACIONES CONTABLES Y AJUSTES MENSUALES SEGÚN LAS OBSERVACIONES DEL ÁREA CONTABLE O AUDITORÍA, CORRIGIENDO REGISTROS MAL CLASIFICADOS O INCONSISTENCIAS DETECTADAS. | L25: CON ACTIVIDAD | N25: 0.44027778 | O25: 0.44375 | P25: =IF(MUESTREO_LABORAL_A2[[#This Row],[TIEMPO INICIO]]="","",(MUESTREO_LABORAL_A2[[#This Row],[TIEMPO FIN]]-MUESTREO_LABORAL_A2[[#This Row],[TIEMPO INICIO]])*24) -> 0.083333333
B26: TSER | C26: CONTABILIDAD | D26: ANALISTA CONTABLE 2 EXPORTADORAS | E26: GERALDINE NAULA | F26: 45973 | I26: FACTURACIÓN CIF BANANO A CLIENTES EN MULTINATIONAL | J26: =IFERROR(VLOOKUP(MUESTREO_LABORAL_A2[[#This Row],[ACTIVIDAD]],'Lista Maestra'!$D$6:$F$190,3,0),"") -> FACTURACIÓN A CLIENTES | K26: =IFERROR(VLOOKUP(MUESTREO_LABORAL_A2[[#This Row],[ACTIVIDAD]],'Lista Maestra'!$D$6:$F$190,2,0),"") -> ELABORACIÓN SEMANAL DE FACTURAS DE BANANO PARA CLIENTES INTERNACIONALES EN MULTINATIONAL, TRABAJANDO CON LOS REPORTES DE TRÁMITES DE LA SEMANA, DETALLE DE CONSOLIDACIÓN EN FTL Y B/LS CON CIERRE SEMANAL CORRESPONDIENTE. | L26: CON ACTIVIDAD | N26: 0.44375 | O26: 0.47361111 | P26: =IF(MUESTREO_LABORAL_A2[[#This Row],[TIEMPO INICIO]]="","",(MUESTREO_LABORAL_A2[[#This Row],[TIEMPO FIN]]-MUESTREO_LABORAL_A2[[#This Row],[TIEMPO INICIO]])*24) -> 0.71666667 | Q26: A la espera de la información de Jennifer Medranda. SIIM MAERSK
B27: TSER | C27: CONTABILIDAD | D27: ANALISTA CONTABLE 2 EXPORTADORAS | E27: GERALDINE NAULA | F27: 45973 | I27: FACTURACIÓN CIF PLÁTANO A CLIENTES EN MULTINATIONAL | J27: =IFERROR(VLOOKUP(MUESTREO_LABORAL_A2[[#This Row],[ACTIVIDAD]],'Lista Maestra'!$D$6:$F$190,3,0),"") -> FACTURACIÓN A CLIENTES | K27: =IFERROR(VLOOKUP(MUESTREO_LABORAL_A2[[#This Row],[ACTIVIDAD]],'Lista Maestra'!$D$6:$F$190,2,0),"") -> ELABORACIÓN SEMANAL DE FACTURAS DE PLATANO PARA CLIENTES INTERNACIONALES EN MULTINATIONAL, TRABAJANDO CON LOS REPORTES DE TRÁMITES DE LA SEMANA, DETALLE DE CONSOLIDACIÓN EN FTL Y B/LS CON CIERRE SEMANAL CORRESPONDIENTE. | L27: CON ACTIVIDAD | N27: 0.47361111 | O27: 0.4875 | P27: =IF(MUESTREO_LABORAL_A2[[#This Row],[TIEMPO INICIO]]="","",(MUESTREO_LABORAL_A2[[#This Row],[TIEMPO FIN]]-MUESTREO_LABORAL_A2[[#This Row],[TIEMPO INICIO]])*24) -> 0.33333333 | Q27: A la espera de la información de Jennifer Medranda. P&A
B28: TSER | C28: CONTABILIDAD | D28: ANALISTA CONTABLE 2 EXPORTADORAS | E28: GERALDINE NAULA | F28: 45973 | I28: COMPARATIVO VENTAS MLC Y DECLARACION COFACE | J28: =IFERROR(VLOOKUP(MUESTREO_LABORAL_A2[[#This Row],[ACTIVIDAD]],'Lista Maestra'!$D$6:$F$190,3,0),"") -> ANÁLISIS DE VENTAS | K28: =IFERROR(VLOOKUP(MUESTREO_LABORAL_A2[[#This Row],[ACTIVIDAD]],'Lista Maestra'!$D$6:$F$190,2,0),"") -> REALIZAR REPORTE, ANALISIS, COMPARACIÓN Y REVISIÓN DE LA INFORMACIÓN RECIBIDA POR CORREO DEL ÁREA FINANCIERA, VERIFICANDO QUE LO DECLARADO A COFACE COINCIDA CON LAS VENTAS REGISTRADAS EN LA CONTABILIDAD POR CLIENTE EN MULTINATIONAL. | L28: CON ACTIVIDAD | N28: 0.4875 | O28: 0.51388889 | P28: =IF(MUESTREO_LABORAL_A2[[#This Row],[TIEMPO INICIO]]="","",(MUESTREO_LABORAL_A2[[#This Row],[TIEMPO FIN]]-MUESTREO_LABORAL_A2[[#This Row],[TIEMPO INICIO]])*24) -> 0.63333333
B29: TSER | C29: CONTABILIDAD | D29: ANALISTA CONTABLE 2 EXPORTADORAS | E29: GERALDINE NAULA | F29: 45973 | I29: NECESIDADES BIOLÓGICAS | J29: =IFERROR(VLOOKUP(MUESTREO_LABORAL_A2[[#This Row],[ACTIVIDAD]],'Lista Maestra'!$D$6:$F$190,3,0),"") -> NECESIDADES BIOLÓGICAS | K29: =IFERROR(VLOOKUP(MUESTREO_LABORAL_A2[[#This Row],[ACTIVIDAD]],'Lista Maestra'!$D$6:$F$190,2,0),"") -> PROCESO DE MICCIÓN Y AGREGADOS | L29: CON ACTIVIDAD | N29: 0.51388889 | O29: 0.51875 | P29: =IF(MUESTREO_LABORAL_A2[[#This Row],[TIEMPO INICIO]]="","",(MUESTREO_LABORAL_A2[[#This Row],[TIEMPO FIN]]-MUESTREO_LABORAL_A2[[#This Row],[TIEMPO INICIO]])*24) -> 0.11666667
B30: TSER | C30: CONTABILIDAD | D30: ANALISTA CONTABLE 2 EXPORTADORAS | E30: GERALDINE NAULA | F30: 45973 | I30: EMISIÓN CERTIFICADOS DE EXPORTACIÓN | J30: =IFERROR(VLOOKUP(MUESTREO_LABORAL_A2[[#This Row],[ACTIVIDAD]],'Lista Maestra'!$D$6:$F$190,3,0),"") -> EMISIÓN CERTIFICADOS | K30: =IFERROR(VLOOKUP(MUESTREO_LABORAL_A2[[#This Row],[ACTIVIDAD]],'Lista Maestra'!$D$6:$F$190,2,0),"") -> ELABORACIÓN DE CERTIFICADOS PARA PRODUCTORES SEGÚN LOS MESES SOLICITADOS, INCLUYENDO EL DETALLE DE DAE, NÚMERO DE FACTURA DE VENTA, CANTIDAD DE CAJAS EXPORTADAS, FECHA DE CIERRE DE LAS DAE, VALOR TOTAL EN USD Y FACTURA DE COMPRA DEL PROVEEDOR. | L30: CON ACTIVIDAD | N30: 0.51875 | O30: 0.52083333 | P30: =IF(MUESTREO_LABORAL_A2[[#This Row],[TIEMPO INICIO]]="","",(MUESTREO_LABORAL_A2[[#This Row],[TIEMPO FIN]]-MUESTREO_LABORAL_A2[[#This Row],[TIEMPO INICIO]])*24) -> 0.05
B31: TSER | C31: CONTABILIDAD | D31: ANALISTA CONTABLE 2 EXPORTADORAS | E31: GERALDINE NAULA | F31: 45973 | I31: ALIMENTACIÓN | J31: =IFERROR(VLOOKUP(MUESTREO_LABORAL_A2[[#This Row],[ACTIVIDAD]],'Lista Maestra'!$D$6:$F$190,3,0),"") -> ALIMENTACIÓN | K31: =IFERROR(VLOOKUP(MUESTREO_LABORAL_A2[[#This Row],[ACTIVIDAD]],'Lista Maestra'!$D$6:$F$190,2,0),"") -> ALIMENTARSE | L31: ALIMENTACIÓN | N31: 0.52083333 | O31: 0.5625 | P31: =IF(MUESTREO_LABORAL_A2[[#This Row],[TIEMPO INICIO]]="","",(MUESTREO_LABORAL_A2[[#This Row],[TIEMPO FIN]]-MUESTREO_LABORAL_A2[[#This Row],[TIEMPO INICIO]])*24) -> 1
B32: TSER | C32: CONTABILIDAD | D32: ANALISTA CONTABLE 2 EXPORTADORAS | E32: GERALDINE NAULA | F32: 45973 | I32: FACTURACIÓN CIF BANANO A CLIENTES EN MULTINATIONAL | J32: =IFERROR(VLOOKUP(MUESTREO_LABORAL_A2[[#This Row],[ACTIVIDAD]],'Lista Maestra'!$D$6:$F$190,3,0),"") -> FACTURACIÓN A CLIENTES | K32: =IFERROR(VLOOKUP(MUESTREO_LABORAL_A2[[#This Row],[ACTIVIDAD]],'Lista Maestra'!$D$6:$F$190,2,0),"") -> ELABORACIÓN SEMANAL DE FACTURAS DE BANANO PARA CLIENTES INTERNACIONALES EN MULTINATIONAL, TRABAJANDO CON LOS REPORTES DE TRÁMITES DE LA SEMANA, DETALLE DE CONSOLIDACIÓN EN FTL Y B/LS CON CIERRE SEMANAL CORRESPONDIENTE. | L32: CON ACTIVIDAD | N32: 0.5625 | O32: 0.58263889 | P32: =IF(MUESTREO_LABORAL_A2[[#This Row],[TIEMPO INICIO]]="","",(MUESTREO_LABORAL_A2[[#This Row],[TIEMPO FIN]]-MUESTREO_LABORAL_A2[[#This Row],[TIEMPO INICIO]])*24) -> 0.48333333
B33: TSER | C33: CONTABILIDAD | D33: ANALISTA CONTABLE 2 EXPORTADORAS | E33: GERALDINE NAULA | F33: 45973 | I33: EMISIÓN CERTIFICADOS DE EXPORTACIÓN | J33: =IFERROR(VLOOKUP(MUESTREO_LABORAL_A2[[#This Row],[ACTIVIDAD]],'Lista Maestra'!$D$6:$F$190,3,0),"") -> EMISIÓN CERTIFICADOS | K33: =IFERROR(VLOOKUP(MUESTREO_LABORAL_A2[[#This Row],[ACTIVIDAD]],'Lista Maestra'!$D$6:$F$190,2,0),"") -> ELABORACIÓN DE CERTIFICADOS PARA PRODUCTORES SEGÚN LOS MESES SOLICITADOS, INCLUYENDO EL DETALLE DE DAE, NÚMERO DE FACTURA DE VENTA, CANTIDAD DE CAJAS EXPORTADAS, FECHA DE CIERRE DE LAS DAE, VALOR TOTAL EN USD Y FACTURA DE COMPRA DEL PROVEEDOR. | L33: CON ACTIVIDAD | N33: 0.58263889 | O33: 0.625 | P33: =IF(MUESTREO_LABORAL_A2[[#This Row],[TIEMPO INICIO]]="","",(MUESTREO_LABORAL_A2[[#This Row],[TIEMPO FIN]]-MUESTREO_LABORAL_A2[[#This Row],[TIEMPO INICIO]])*24) -> 1.0166667
B34: TSER | C34: CONTABILIDAD | D34: ANALISTA CONTABLE 2 EXPORTADORAS | E34: GERALDINE NAULA | F34: 45974 | I34: FACTURACIÓN CIF BANANO A CLIENTES EN MULTINATIONAL | J34: =IFERROR(VLOOKUP(MUESTREO_LABORAL_A2[[#This Row],[ACTIVIDAD]],'Lista Maestra'!$D$6:$F$190,3,0),"") -> FACTURACIÓN A CLIENTES | K34: =IFERROR(VLOOKUP(MUESTREO_LABORAL_A2[[#This Row],[ACTIVIDAD]],'Lista Maestra'!$D$6:$F$190,2,0),"") -> ELABORACIÓN SEMANAL DE FACTURAS DE BANANO PARA CLIENTES INTERNACIONALES EN MULTINATIONAL, TRABAJANDO CON LOS REPORTES DE TRÁMITES DE LA SEMANA, DETALLE DE CONSOLIDACIÓN EN FTL Y B/LS CON CIERRE SEMANAL CORRESPONDIENTE. | L34: CON ACTIVIDAD | N34: 0.35416667 | O34: 0.37708333 | P34: =IF(MUESTREO_LABORAL_A2[[#This Row],[TIEMPO INICIO]]="","",(MUESTREO_LABORAL_A2[[#This Row],[TIEMPO FIN]]-MUESTREO_LABORAL_A2[[#This Row],[TIEMPO INICIO]])*24) -> 0.55
B35: TSER | C35: CONTABILIDAD | D35: ANALISTA CONTABLE 2 EXPORTADORAS | E35: GERALDINE NAULA | F35: 45974 | I35: FACTURACIÓN CIF PLÁTANO A CLIENTES EN MULTINATIONAL | J35: =IFERROR(VLOOKUP(MUESTREO_LABORAL_A2[[#This Row],[ACTIVIDAD]],'Lista Maestra'!$D$6:$F$190,3,0),"") -> FACTURACIÓN A CLIENTES | K35: =IFERROR(VLOOKUP(MUESTREO_LABORAL_A2[[#This Row],[ACTIVIDAD]],'Lista Maestra'!$D$6:$F$190,2,0),"") -> ELABORACIÓN SEMANAL DE FACTURAS DE PLATANO PARA CLIENTES INTERNACIONALES EN MULTINATIONAL, TRABAJANDO CON LOS REPORTES DE TRÁMITES DE LA SEMANA, DETALLE DE CONSOLIDACIÓN EN FTL Y B/LS CON CIERRE SEMANAL CORRESPONDIENTE. | L35: CON ACTIVIDAD | N35: 0.37708333 | O35: 0.40208333 | P35: =IF(MUESTREO_LABORAL_A2[[#This Row],[TIEMPO INICIO]]="","",(MUESTREO_LABORAL_A2[[#This Row],[TIEMPO FIN]]-MUESTREO_LABORAL_A2[[#This Row],[TIEMPO INICIO]])*24) -> 0.6
B36: TSER | C36: CONTABILIDAD | D36: ANALISTA CONTABLE 2 EXPORTADORAS | E36: GERALDINE NAULA | F36: 45974 | I36: SOPORTE MEDIANTE AUDITORÍA EXTERNAS E INTERNAS | J36: =IFERROR(VLOOKUP(MUESTREO_LABORAL_A2[[#This Row],[ACTIVIDAD]],'Lista Maestra'!$D$6:$F$190,3,0),"") -> SOPORTE AUDITORÍA | K36: =IFERROR(VLOOKUP(MUESTREO_LABORAL_A2[[#This Row],[ACTIVIDAD]],'Lista Maestra'!$D$6:$F$190,2,0),"") -> PROPORCIONAR SOPORTE EN AUDITORÍAS TRIBUTARIAS, DE CARBONO NEUTRO Y OTROS PROCESOS DE CONTROL FINANCIERO. | L36: CON ACTIVIDAD | N36: 0.40208333 | O36: 0.44861111 | P36: =IF(MUESTREO_LABORAL_A2[[#This Row],[TIEMPO INICIO]]="","",(MUESTREO_LABORAL_A2[[#This Row],[TIEMPO FIN]]-MUESTREO_LABORAL_A2[[#This Row],[TIEMPO INICIO]])*24) -> 1.1166667
B37: TSER | C37: CONTABILIDAD | D37: ANALISTA CONTABLE 2 EXPORTADORAS | E37: GERALDINE NAULA | F37: 45974 | I37: ELABORACIÓN DE REPORTES FINANCIEROS | J37: =IFERROR(VLOOKUP(MUESTREO_LABORAL_A2[[#This Row],[ACTIVIDAD]],'Lista Maestra'!$D$6:$F$190,3,0),"") -> REPORTERÍA | K37: =IFERROR(VLOOKUP(MUESTREO_LABORAL_A2[[#This Row],[ACTIVIDAD]],'Lista Maestra'!$D$6:$F$190,2,0),"") -> ELABORAR REPORTERÍA FINANCIERA MENSUAL PARA ELABORACIÓN DE BALANCES. | L37: CON ACTIVIDAD | N37: 0.44861111 | O37: 0.48819444 | P37: =IF(MUESTREO_LABORAL_A2[[#This Row],[TIEMPO INICIO]]="","",(MUESTREO_LABORAL_A2[[#This Row],[TIEMPO FIN]]-MUESTREO_LABORAL_A2[[#This Row],[TIEMPO INICIO]])*24) -> 0.95
B38: TSER | C38: CONTABILIDAD | D38: ANALISTA CONTABLE 2 EXPORTADORAS | E38: GERALDINE NAULA | F38: 45974 | I38: CREACIÓN Y ACTUALIZACIÓN DE ARTÍCULOS Y CUENTAS CONTABLES EN SAP | J38: =IFERROR(VLOOKUP(MUESTREO_LABORAL_A2[[#This Row],[ACTIVIDAD]],'Lista Maestra'!$D$6:$F$190,3,0),"") -> CREACIÓN DE ARTÍCULOS | K38: =IFERROR(VLOOKUP(MUESTREO_LABORAL_A2[[#This Row],[ACTIVIDAD]],'Lista Maestra'!$D$6:$F$190,2,0),"") -> SE REALIZA LA CREACIÓN Y ACTUALIZACIÓN DE ARTÍCULOS Y CUENTAS CONTABLES DE BIENES O SERVICIOS EN SAP, SEGÚN LOS REQUERIMIENTOS DE LAS DEMÁS ÁREAS. | L38: CON ACTIVIDAD | N38: 0.48819444 | O38: 0.49513889 | P38: =IF(MUESTREO_LABORAL_A2[[#This Row],[TIEMPO INICIO]]="","",(MUESTREO_LABORAL_A2[[#This Row],[TIEMPO FIN]]-MUESTREO_LABORAL_A2[[#This Row],[TIEMPO INICIO]])*24) -> 0.16666667
B39: TSER | C39: CONTABILIDAD | D39: ANALISTA CONTABLE 2 EXPORTADORAS | E39: GERALDINE NAULA | F39: 45974 | I39: ELABORACIÓN DE REPORTES FINANCIEROS | J39: =IFERROR(VLOOKUP(MUESTREO_LABORAL_A2[[#This Row],[ACTIVIDAD]],'Lista Maestra'!$D$6:$F$190,3,0),"") -> REPORTERÍA | K39: =IFERROR(VLOOKUP(MUESTREO_LABORAL_A2[[#This Row],[ACTIVIDAD]],'Lista Maestra'!$D$6:$F$190,2,0),"") -> ELABORAR REPORTERÍA FINANCIERA MENSUAL PARA ELABORACIÓN DE BALANCES. | L39: CON ACTIVIDAD | N39: 0.49513889 | O39: 0.52083333 | P39: =IF(MUESTREO_LABORAL_A2[[#This Row],[TIEMPO INICIO]]="","",(MUESTREO_LABORAL_A2[[#This Row],[TIEMPO FIN]]-MUESTREO_LABORAL_A2[[#This Row],[TIEMPO INICIO]])*24) -> 0.61666667
... B41: TSER | C41: CONTABILIDAD | D41: ANALISTA CONTABLE 2 EXPORTADORAS | E41: GERALDINE NAULA | F41: 45974 | I41: ELABORACIÓN DE REPORTES FINANCIEROS | J41: =IFERROR(VLOOKUP(MUESTREO_LABORAL_A2[[#This Row],[ACTIVIDAD]],'Lista Maestra'!$D$6:$F$190,3,0),"") -> REPORTERÍA | K41: =IFERROR(VLOOKUP(MUESTREO_LABORAL_A2[[#This Row],[ACTIVIDAD]],'Lista Maestra'!$D$6:$F$190,2,0),"") -> ELABORAR REPORTERÍA FINANCIERA MENSUAL PARA ELABORACIÓN DE BALANCES. | L41: CON ACTIVIDAD | N41: 0.5625 | O41: 0.625 | P41: =IF(MUESTREO_LABORAL_A2[[#This Row],[TIEMPO INICIO]]="","",(MUESTREO_LABORAL_A2[[#This Row],[TIEMPO FIN]]-MUESTREO_LABORAL_A2[[#This Row],[TIEMPO INICIO]])*24) -> 1.5
B42: TSER | C42: CONTABILIDAD | D42: ANALISTA CONTABLE 2 EXPORTADORAS | E42: GERALDINE NAULA | F42: 45975 | I42: EMISIÓN CERTIFICADOS DE EXPORTACIÓN | J42: =IFERROR(VLOOKUP(MUESTREO_LABORAL_A2[[#This Row],[ACTIVIDAD]],'Lista Maestra'!$D$6:$F$190,3,0),"") -> EMISIÓN CERTIFICADOS | K42: =IFERROR(VLOOKUP(MUESTREO_LABORAL_A2[[#This Row],[ACTIVIDAD]],'Lista Maestra'!$D$6:$F$190,2,0),"") -> ELABORACIÓN DE CERTIFICADOS PARA PRODUCTORES SEGÚN LOS MESES SOLICITADOS, INCLUYENDO EL DETALLE DE DAE, NÚMERO DE FACTURA DE VENTA, CANTIDAD DE CAJAS EXPORTADAS, FECHA DE CIERRE DE LAS DAE, VALOR TOTAL EN USD Y FACTURA DE COMPRA DEL PROVEEDOR. | L42: CON ACTIVIDAD | N42: 0.35416667 | O42: 0.4 | P42: =IF(MUESTREO_LABORAL_A2[[#This Row],[TIEMPO INICIO]]="","",(MUESTREO_LABORAL_A2[[#This Row],[TIEMPO FIN]]-MUESTREO_LABORAL_A2[[#This Row],[TIEMPO INICIO]])*24) -> 1.1 | Q42: Hoy revisaré el flujo de multinational eso es un excel compartido que tenemos con juanjo de comercial y el en este excel registra todas las facturas de proveedores que son emitidas a multinational como sabes multinational es de USA entonces no esta en el portal del SRI Por ese motivo se creo este flujo, para tener un mayor control ese lo usamos juan, angelo y yo juanjo llena el excel, yo lo reviso y hago los ingresos de fc correspondiente y angelo mira lo que esta ingresado y paga asi nos manejamos
B43: TSER | C43: CONTABILIDAD | D43: ANALISTA CONTABLE 2 EXPORTADORAS | E43: GERALDINE NAULA | F43: 45975 | I43: FACTURACIÓN DDP BANANO COSTCO | J43: =IFERROR(VLOOKUP(MUESTREO_LABORAL_A2[[#This Row],[ACTIVIDAD]],'Lista Maestra'!$D$6:$F$190,3,0),"") -> FACTURACIÓN A CLIENTES | K43: =IFERROR(VLOOKUP(MUESTREO_LABORAL_A2[[#This Row],[ACTIVIDAD]],'Lista Maestra'!$D$6:$F$190,2,0),"") -> ELABORACIÓN SEMANAL DE FACTURAS DE BANANO PARA CLIENTES INTERNACIONALES EN MULTINATIONAL, TRABAJANDO CON LOS REPORTES DE TRÁMITES DE LA SEMANA, DETALLE DE CONSOLIDACIÓN EN FTL Y B/LS, FACTURACIÓN SE REALIZA 21 DÍAS DESPUES DEL ZARPE DE LA CARGA | L43: CON ACTIVIDAD | N43: 0.4 | O43: 0.45347222 | P43: =IF(MUESTREO_LABORAL_A2[[#This Row],[TIEMPO INICIO]]="","",(MUESTREO_LABORAL_A2[[#This Row],[TIEMPO FIN]]-MUESTREO_LABORAL_A2[[#This Row],[TIEMPO INICIO]])*24) -> 1.2833333
...

Sheet Hoja1
D5: REUNIONES | E5: PROVEEDORES | F5: ENTRADAS | G5: PROCESO | H5: SALIDAS | I5: CLIENTES
D6: REALIZADO | E6: DANNY | F6: CONSOLIDADDO FTL/CONTROL PLÁTANO/ANTICIPO DE PAGO A PRODUCTORES/MAQUILAJE Y PALETIZADO | G6: CONTROL PLÁTANO | H6: PAGOS A PRODUCTORES/DATOS PARA FACTURACIÓN/DATOS DE LIQUIDACIÓN/DECLARACIÓN DE PLANES DE EMBARQUE PARA COMEX/FACTURACIÓN (MARLYS [REGISTRO DE FACTURAS DE FRUTA]/HAIDEY [FACTURACIÓN DE VENTA Y FACTURACIÓN REEMBOLSOS]) | I6: COMEX/TESORERIA
D7: REALIZADO | E7: MARITZA | F7: VENTAS DE MATERIALES
E8: ANDREA | F8: RESULTADOS DE CUENTAS POR COBRAR
E9: CESAR VALLE | F9: PLANES DE EMBARQUE
E10: MELANIE MIRANDA | F10: DESCUENTO DE TRANSPORTE DE MATERIALES

Sheet Lista Maestra
C5: EMPRESA | D5: ACTIVIDAD | E5: ACCIONES | F5: PROCESO | G5: TIPO DE ANALISIS | H5: DESCRIPCIÓN
C6: TSER | D6: FACTURACIÓN CIF BANANO A CLIENTES EN MULTINATIONAL | E6: ELABORACIÓN SEMANAL DE FACTURAS DE BANANO PARA CLIENTES INTERNACIONALES EN MULTINATIONAL, TRABAJANDO CON LOS REPORTES DE TRÁMITES DE LA SEMANA, DETALLE DE CONSOLIDACIÓN EN FTL Y B/LS CON CIERRE SEMANAL CORRESPONDIENTE. | F6: FACTURACIÓN A CLIENTES | G6: AUTOMATIZACIÓN | H6: Cuando se pueden realizar proyectos de mejora para reducir tiempos en actividades.
C7: TSER | D7: FACTURACIÓN CIF PLÁTANO A CLIENTES EN MULTINATIONAL | E7: ELABORACIÓN SEMANAL DE FACTURAS DE PLATANO PARA CLIENTES INTERNACIONALES EN MULTINATIONAL, TRABAJANDO CON LOS REPORTES DE TRÁMITES DE LA SEMANA, DETALLE DE CONSOLIDACIÓN EN FTL Y B/LS CON CIERRE SEMANAL CORRESPONDIENTE. | F7: FACTURACIÓN A CLIENTES | G7: ENC | H7: Es una entrada no conforme cuando las salidas de un proceso abajo (otro departamento) no envía la información correcta o la envía incompleta, lo cual genera pérdidas de tiempos en las actividades. Se debe colocar en la columna DEPARTAMENTO ENC el Departamento que genera la entrada no conforme.
C8: TSER | D8: CONSOLIDACIÓN DE VENTAS CÍAS RELACIONADAS A MLC | E8: REALIZACIÓN Y ANÁLISIS DE CONCILIACIONES DE VENTAS ENTRE EXPORTADORAS RELACIONADAS PARA VERIFICAR QUE LOS REGISTROS DE VENTAS ESTÉN CUADRADOS, IDENTIFICANDO DIFERENCIAS Y REGISTRANDO AJUSTES CONTABLES NECESARIOS. | F8: CONCILIACIÓN DE VENTAS Y COMPRAS ENTRE RELACIONADAS | G8: SA | H8: Cuando el colaborador no cuenta con actividades en el horario laboral o realiza actividades que no corresponden al cargo.
C9: TSER | D9: EMISIÓN DE NOTAS DE CRÉDITOS CLIENTES EN MULTINATIONAL (BANANO Y PLÁTANO) | E9: ELABORACIÓN DE NOTAS DE CRÉDITO SEGÚN AJUSTES DE PRECIOS, RECLAMOS DE FRUTAS, DEVOLUCIONES, VERIFICACIÓN DE MONTOS Y CLIENTES, REGISTRO DE LOS ASIENTOS CORRESPONDIENTES EN SAP, Y ACTUALIZACIÓN DE CUENTAS POR COBRAR. | F9: NOTAS DE CRÉDITO CLIENTES | G9: FALLO IT | H9: Cuando el sistema no permite que el colaborador avance con sus actividades debido a que no puede utilizar su computadora personal.
C10: TSER | D10: FACTURACIÓN DDP BANANO COSTCO | E10: ELABORACIÓN SEMANAL DE FACTURAS DE BANANO PARA CLIENTES INTERNACIONALES EN MULTINATIONAL, TRABAJANDO CON LOS REPORTES DE TRÁMITES DE LA SEMANA, DETALLE DE CONSOLIDACIÓN EN FTL Y B/LS, FACTURACIÓN SE REALIZA 21 DÍAS DESPUES DEL ZARPE DE LA CARGA | F10: FACTURACIÓN A CLIENTES | G10: CAPACITACIÓN | H10: Cuando un colaborador carece de expertiz en el desarrollo de una actividad como el uso de una herramienta técnológica o de comunicación.
C11: TSER | D11: EMISIÓN CERTIFICADOS DE EXPORTACIÓN | E11: ELABORACIÓN DE CERTIFICADOS PARA PRODUCTORES SEGÚN LOS MESES SOLICITADOS, INCLUYENDO EL DETALLE DE DAE, NÚMERO DE FACTURA DE VENTA, CANTIDAD DE CAJAS EXPORTADAS, FECHA DE CIERRE DE LAS DAE, VALOR TOTAL EN USD Y FACTURA DE COMPRA DEL PROVEEDOR. | F11: EMISIÓN CERTIFICADOS | G11: CON ACTIVIDAD | H11: Cuando el colaborador se encuentre realizando actividades que corresponden al cargo sin ningun tipo de retraso alguno.
C12: TSER | D12: REVISIÓN, GESTIÓN Y CONTROL DEL FLUJO DE CUENTAS POR PAGAR (INVOICES-MLC) MULTINATIONAL | E12: REGISTRO Y ANÁLISIS DE FACTURAS DE PROVEEDORES DEL EXTERIOR EN EL SISTEMA CONTABLE, SEGÚN APROBACIÓN DEL EQUIPO COMERCIAL, INCLUYENDO FACTURAS DE INSPECCIONES ADICIONALES A CONTENEDORES EXPORTADOS, YA SEA DE FORMA SEMANAL O MENSUAL (PROVEEDORES COMO SEABOARD, J&K, LARAS TRUCKING, RENE VELASQUEZ, HPL APOLLO, ETC.), VERIFICACIÓN Y ANÁLISIS DE DATOS Y MONTOS. | F12: CONTROL CUENTAS POR PAGAR | G12: DEFINICIÓN | H12: Inducción del muestreo de funciones a realizar en el balance de cargas de trabajo.
C13: TSER | D13: ASIENTOS POR DESCUENTOS A EMPLEADOS MEDIANTE ROL | E13: REGISTRO Y ANÁLISIS DE ASIENTOS DE DIARIO O DE RECLASIFICACIÓN EN CUENTAS POR COBRAR DE EMPLEADOS POR DESCUENTOS INDICADOS POR EL ÁREA DE RRHH, VERIFICANDO LA CONSISTENCIA DE MONTOS, CLASIFICACIÓN CONTABLE CORRECTA | F13: DESCUENTOS DE NÓMINA | G13: ALIMENTACIÓN | H13: Servicios de alimentación
C14: TSER | D14: ANALISIS Y CONCILIACION DE CUENTAS CONTABLES MENSUALES | E14: REALIZAR EL ANÁLISIS DETALLADO DE LAS CUENTAS CONTABLES MENSUALES, COMPARANDO SALDOS Y MOVIMIENTOS PARA IDENTIFICAR DISCREPANCIAS. | F14: ANÁLISIS DE CUENTAS | G14: NECESIDADES BIOLÓGICAS
C15: TSER | D15: CONCILIACION DE COMPRAS, VENTAS, SALDOS EN CUENTAS POR COBRAR ENTRE COMPAÑÍAS RELACIONADAS | E15: REALIZAR LA CONCILIACIÓN DE COMPRAS, VENTAS Y SALDOS EN CUENTAS POR COBRAR ENTRE COMPAÑÍAS RELACIONADAS, VERIFICANDO LA COHERENCIA DE LOS REGISTROS CONTABLES, DETECTANDO DIFERENCIAS Y REGISTRANDO LOS AJUSTES NECESARIOS | F15: CONCILIACIÓN RELACIONADAS
C16: TSER | D16: ELABORACIÓN DE REPORTES FINANCIEROS | E16: ELABORAR REPORTERÍA FINANCIERA MENSUAL PARA ELABORACIÓN DE BALANCES. | F16: REPORTERÍA
C17: TSER | D17: COMPARATIVO VENTAS MLC Y DECLARACION COFACE | E17: REALIZAR REPORTE, ANALISIS, COMPARACIÓN Y REVISIÓN DE LA INFORMACIÓN RECIBIDA POR CORREO DEL ÁREA FINANCIERA, VERIFICANDO QUE LO DECLARADO A COFACE COINCIDA CON LAS VENTAS REGISTRADAS EN LA CONTABILIDAD POR CLIENTE EN MULTINATIONAL. | F17: ANÁLISIS DE VENTAS
C18: TSER | D18: SOPORTE MEDIANTE AUDITORÍA EXTERNAS E INTERNAS | E18: PROPORCIONAR SOPORTE EN AUDITORÍAS TRIBUTARIAS, DE CARBONO NEUTRO Y OTROS PROCESOS DE CONTROL FINANCIERO. | F18: SOPORTE AUDITORÍA
C19: TSER | D19: ASISTENCIA TÉCNICA EN LA DETERMINACION DE RETENCIONES TRIBUTARIAS | E19: BRINDAR ASISTENCIA TÉCNICA EN LA DETERMINACIÓN DE RETENCIONES TRIBUTARIAS A LOS PRVOEEDORES, INCLUYENDO CÁLCULO SEGÚN NORMATIVA VIGENTE. | F19: ASISTENCIA EN IMPUESTO TRIBUTARIO
C20: TSER | D20: GESTIÓN CONTABLE Y CLASIFICACIÓN DE CUENTAS FINANCIERAS | E20: SE REALIZA LA GESTIÓN CONTABLE Y CLASIFICACIÓN DE CUENTAS FINANCIERAS, MEDIANTE LA REVISIÓN, ANÁLISIS Y REGISTRO DE LOS MOVIMIENTOS CONTABLES EN EL SISTEMA. SE CLASIFICAN LAS TRANSACCIONES SEGÚN SU NATURALEZA (ACTIVOS, PASIVOS, INGRESOS Y GASTOS) | F20: ANÁLISIS DE CUENTAS
C21: TSER | D21: GESTIÓN DE REPOSICIÓN Y CONTROL DE CAJA CHICA EL CARMEN Y EL PAN | E21: SE EJECUTA LA GESTIÓN DE REPOSICIÓN Y CONTROL DE CAJA CHICA, MEDIANTE LA REVISIÓN DE COMPROBANTES DE GASTO, VALIDACIÓN DE SOPORTES Y REGISTRO CONTABLE DE LOS MOVIMIENTOS EFECTUADOS. SE VERIFICA QUE LOS GASTOS SE ENCUENTREN DENTRO DE LAS POLÍTICAS INTERNAS Y SE PREPARA LA SOLICITUD DE REPOSICIÓN CORRESPONDIENTE. | F21: CONTROL DE CAJA CHICA
C22: TSER | D22: APOYO EN DECLARACIONS, ATS Y ANEXOS | E22: SE BRINDA APOYO EN LA ELABORACIÓN DE DECLARACIONES TRIBUTARIAS, ATS Y ANEXOS, MEDIANTE REPORTERÍA Y REVISIÓN DE INFORMACIÓN CONTABLE, VALIDANDO LOS DATOS REGISTRADOS EN EL SISTEMA. | F22: SOPORTE SRI
C23: TSER | D23: SUPERVISIÓN DE CIERRE CONTABLE EN CUENTAS POR PAGAR MENSUAL Y ANUAL | E23: SE EJECUTA LA SUPERVISIÓN Y EJECUCIÓN DEL CIERRE CONTABLE MENSUAL Y ANUAL DE LAS CUENTAS POR PAGAR, REVISANDO LOS REGISTROS DE FACTURAS DE COMPRA, RETENCIONES Y FACTURAS DE VENTA, ASÍ COMO LAS RECLASIFICACIONES NECESARIAS PARA MANTENER CORRECTA CONTABILIZACION DE GASTOS. | F23: SUPERVISIÓN EN CIERRE
C24: TSER | D24: CREACIÓN Y ACTUALIZACIÓN DE ARTÍCULOS Y CUENTAS CONTABLES EN SAP | E24: SE REALIZA LA CREACIÓN Y ACTUALIZACIÓN DE ARTÍCULOS Y CUENTAS CONTABLES DE BIENES O SERVICIOS EN SAP, SEGÚN LOS REQUERIMIENTOS DE LAS DEMÁS ÁREAS. | F24: CREACIÓN DE ARTÍCULOS
C25: TSER | D25: REVISION Y ANALISIS DE CUENTAS INGRESOS, COSTOS Y GASTOS | E25: SE REVISA Y ANALIZA LA INFORMACIÓN DE LAS CUENTAS DE INGRESOS, COSTOS Y GASTOS, VERIFICANDO QUE LOS REGISTROS CONTABLES ESTÉN CORRECTOS Y RESPALDADOS CON SU DOCUMENTACIÓN. SE COMPARAN LOS VALORES ENTRE PERIODOS Y SE IDENTIFICAN DIFERENCIAS PARA REALIZAR LOS AJUSTES O RECLASIFICACIONES NECESARIAS. | F25: ANÁLISIS DE CUENTAS
C26: TSER | D26: CONTROL DE CUENTAS POR PAGAR Y REVISIÓN DE GASTOS OPERATIVOS EN EXPORTADORAS | E26: SE REVISA Y CONTROLA LA INFORMACIÓN DE LAS CUENTAS POR PAGAR DE LAS EXPORTADORAS, VERIFICANDO QUE LAS FACTURAS DE COMPRA Y GASTOS OPERATIVOS ESTÉN CORRECTAMENTE REGISTRADOS, APROBADOS Y RESPALDADOS. SE REALIZAN SEGUIMIENTOS A LOS PROVEEDORES Y SE CONFIRMA QUE LOS VALORES COINCIDAN CON LOS REGISTROS CONTABLES. | F26: SUPERVISIÓN EN CIERRE
... C34: TSER | D34: REUNIONES Y COMITÉS | E34: SE PARTICIPA EN REUNIONES Y COMITÉS, DISCUTIENDO ASUNTOS CONTABLES Y COORDINANDO ACCIONES CON OTROS DEPARTAMENTOS PARA DAR SEGUIMIENTO A PROCESOS, AJUSTES Y REPORTES CONTABLES. | F34: REUNIONES
C35: TSER | D35: LIQUIDACIÓN - GASTOS ARROZ | F35: LIQUIDACIÓN DE GASTOS
C36: TSER | D36: SOPORTE INGRESO DE FACTURAS DE COMPRAS | F36: SUPERVISIÓN EN CIERRE
C37: TSER | D37: NECESIDADES BIOLÓGICAS | E37: PROCESO DE MICCIÓN Y AGREGADOS | F37: NECESIDADES BIOLÓGICAS
C38: TSER | D38: ALIMENTACIÓN | E38: ALIMENTARSE | F38: ALIMENTACIÓN
C39: TSER | D39: DEFINICIÓN | E39: DEFINIR PROCESOS Y CRITERIOS INGENIERILES | F39: DEFINICIÓN
C40: SMART | D40: REVISIÓN PLANIFICACIÓN DE PIÑAS | F40: PLANIFICACIÓN
C41: SMART | D41: REVISIÓN PROGRAMACIÓN PLÁTANO | F41: PLANIFICACIÓN
C42: SMART | D42: REVISIÓN PROGRAMACIÓN CACAO | F42: PLANIFICACIÓN
C43: SMART | D43: PROGRAMACIÓN DE TRANSPORTE | E43: CUADRE DE VEHÍCULOS EN BASE A LOS CORTES QUE ESTÁN PROGRAMADOS. REVISIÓN SOLICITUD DE OMARSA REVISIÓN LISTADO DE PROVEEDORES DE TRANSPORTE. REVISIÓN ASIGNACIÓN DE CHOFERES TANTO PROVEEDORES DE TRANSPORTE COMO PROVEEDORES PROPIOS. GENERACIÓN DE PLANIFICACIÓN DE TRANSPORTE DEL CORTE DEL MARTES. PLANIFICACIÓN DE BANANO REVISA EN FTL Y SE LO UBICA EN LA BASE DE TRANSPORTE. | F43: RECEPCIÓN DE SOLICITUD DE TRANSPORTE
C44: SMART | D44: REVISIÓN KILOMETRAJE INICIO DE SEMANA | E44: REVISIÓN KILOMETRAJE DE LOS VEHÍCULOS DE SMART DE LA SEMANA ANTERIOR. | F44: CONSOLIDACIÓN
C45: SMART | D45: REVISIÓN PROGRAMACIÓN OPERACIONES | E45: REVISIÓN DE CAMBIOS. LISTA DE ACOPIOS. | F45: PLANIFICACIÓN
C46: SMART | D46: REVISIÓN PROGRAMACIÓN BANANO | F46: PLANIFICACIÓN
C47: SMART | D47: PROGRAMACIÓN DE OLAM | F47: PLANIFICACIÓN
C48: SMART | D48: ELABORACIÓN KILOMETRAJE FINALIZACIÓN | F48: CONSOLIDACIÓN
C49: SMART | D49: RENOVACIÓN DE DOCUMENTOS DE VEHÍCULOS EN PUERTOS | F49: CONTROL DOCUMENTAL DE LA FLOTA
C50: SMART | D50: REVISIÓN PROGRAMACIÓN EN FTL | E50: REVISAR SI HAY ALGÚN CAMBIO QUE HAYA HECHO TROPICAL. TODO CAMBIO DEBE REPORTARSE EN EL GRUPO DE FALLAS VÍA WHATSAPP. | F50: PLANIFICACIÓN
C51: SMART | D51: AJUSTE DE PROGRAMACIÓN DE DESPACHO | E51: CON RESPECTO AL DÍA ANTERIOR. | F51: PLANIFICACIÓN
...

Sheet CONTENIDO DE TRABAJO
C2: EXP GROUP LLC | D2: SEABORAD | G2: WALMART CHILE | H2: KN | I2: EXP GROUP LLC | J2: SEABORAD
C3: 1 PRODUCTO | D3: 1 PRODUCTO | E3: 1 PRODUCTO | F3: 2 PRODUCTOS | G3: 1 PRODUCTO | I3: 1 PRODUCTO
B4: ACTIVIDAD | C4: TIEMPO 1 | D4: TIEMPO 2 | E4: TIEMPO 3 | F4: TIEMPO 4 | G4: TIEMPO 5
B5: FACTURACIÓN CIF BANANO A CLIENTES EN MULTINATIONAL | C5: 6.14.28 | D5: 4.34.27 | E5: 2.58.38 | F5: 4.51.36 | P5: Detalle de trámites | Q5: n factura, puerto destino, n contenedores, n tramite
C6: 1.35.65 | E6: 0.56.35 | F6: 1.39.85 | P6: BL | Q6: peso, n contenedor, nombre producto, n cajas, puerto origen, destino
C7: 0.18.68 | F7: 0.23.02 | P7: Precio | Q7: n articulo, nombre producto, precio
B8: FACTURACIÓN CIF PLÁTANO A CLIENTES EN MULTINATIONAL | G8: 5.58.13 | I8: 3.11.44 | P8: Consolidación | Q8: todo lo anterior
G9: 0.49.44 | I9: 2.03.83
G10: 0.38.26
